Workbook

Sheet Dashboard
B2: NETFLIX TOP 10 — WEEKLY PERFORMANCE DASHBOARD
B3: ="Data through " & TEXT(MAX(Data!B2:B401),"mmmm d, yyyy") & " | Source: Netflix official Top 10 (refresh via Power Query for live data)" -> Data through June 16, 2026 | Source: Netflix official Top 10 (refresh via Power Query for live data)
B5: TOTAL HOURS VIEWED (LATEST WEEK) | D5: TOTAL VIEWS (LATEST WEEK) | F5: TITLES TRACKED (LATEST WEEK) | H5: LONGEST STREAK (WEEKS IN TOP 10) | J5: WEEKS OF HISTORY IN THIS FILE
B6: =SUM(Summary!B3:B6) -> 715182613 | D6: =SUM(Summary!C3:C6) -> 347460919 | F6: =SUM(Summary!D3:D6) -> 40 | H6: =MAX(Data!E2:E401) -> 10 | J6: =COUNTA(Summary!A10:A19) -> 10
B9: ="Longest-running title: " & INDEX(Data!C2:C401,MATCH(MAX(Data!E2:E401),Data!E2:E401,0)) & " (" & MAX(Data!E2:E401) & " weeks in Top 10)" -> Longest-running title: The Last Signal (10 weeks in Top 10)

Sheet Summary
A1: By Category — Most Recent Week
A2: Category | B2: Hours Viewed | C2: Views | D2: Titles in Top 10 | E2: Avg Weeks in Top 10
A3: Films (English) | B3: =SUMIFS(Data!$G$2:$G$401,Data!$A$2:$A$401,$A3,Data!$B$2:$B$401,MAX(Data!$B$2:$B$401)) -> 179796963 | C3: =SUMIFS(Data!$H$2:$H$401,Data!$A$2:$A$401,$A3,Data!$B$2:$B$401,MAX(Data!$B$2:$B$401)) -> 87342213 | D3: =COUNTIFS(Data!$A$2:$A$401,$A3,Data!$B$2:$B$401,MAX(Data!$B$2:$B$401)) -> 10 | E3: =AVERAGEIFS(Data!$E$2:$E$401,Data!$A$2:$A$401,$A3,Data!$B$2:$B$401,MAX(Data!$B$2:$B$401)) -> 6.5
A4: Films (Non-English) | B4: =SUMIFS(Data!$G$2:$G$401,Data!$A$2:$A$401,$A4,Data!$B$2:$B$401,MAX(Data!$B$2:$B$401)) -> 188386440 | C4: =SUMIFS(Data!$H$2:$H$401,Data!$A$2:$A$401,$A4,Data!$B$2:$B$401,MAX(Data!$B$2:$B$401)) -> 89310443 | D4: =COUNTIFS(Data!$A$2:$A$401,$A4,Data!$B$2:$B$401,MAX(Data!$B$2:$B$401)) -> 10 | E4: =AVERAGEIFS(Data!$E$2:$E$401,Data!$A$2:$A$401,$A4,Data!$B$2:$B$401,MAX(Data!$B$2:$B$401)) -> 5.6
A5: TV (English) | B5: =SUMIFS(Data!$G$2:$G$401,Data!$A$2:$A$401,$A5,Data!$B$2:$B$401,MAX(Data!$B$2:$B$401)) -> 147983461 | C5: =SUMIFS(Data!$H$2:$H$401,Data!$A$2:$A$401,$A5,Data!$B$2:$B$401,MAX(Data!$B$2:$B$401)) -> 73420391 | D5: =COUNTIFS(Data!$A$2:$A$401,$A5,Data!$B$2:$B$401,MAX(Data!$B$2:$B$401)) -> 10 | E5: =AVERAGEIFS(Data!$E$2:$E$401,Data!$A$2:$A$401,$A5,Data!$B$2:$B$401,MAX(Data!$B$2:$B$401)) -> 7.1
A6: TV (Non-English) | B6: =SUMIFS(Data!$G$2:$G$401,Data!$A$2:$A$401,$A6,Data!$B$2:$B$401,MAX(Data!$B$2:$B$401)) -> 199015749 | C6: =SUMIFS(Data!$H$2:$H$401,Data!$A$2:$A$401,$A6,Data!$B$2:$B$401,MAX(Data!$B$2:$B$401)) -> 97387872 | D6: =COUNTIFS(Data!$A$2:$A$401,$A6,Data!$B$2:$B$401,MAX(Data!$B$2:$B$401)) -> 10 | E6: =AVERAGEIFS(Data!$E$2:$E$401,Data!$A$2:$A$401,$A6,Data!$B$2:$B$401,MAX(Data!$B$2:$B$401)) -> 5.7
A8: Weekly Trend — Total Hours Viewed (All Categories)
A9: Week | B9: Total Hours Viewed
A10: 46126 | B10: =SUMIFS(Data!$G$2:$G$401,Data!$B$2:$B$401,$A10) -> 778842470
A11: 46133 | B11: =SUMIFS(Data!$G$2:$G$401,Data!$B$2:$B$401,$A11) -> 754250357
A12: 46140 | B12: =SUMIFS(Data!$G$2:$G$401,Data!$B$2:$B$401,$A12) -> 780443663
A13: 46147 | B13: =SUMIFS(Data!$G$2:$G$401,Data!$B$2:$B$401,$A13) -> 740593454
A14: 46154 | B14: =SUMIFS(Data!$G$2:$G$401,Data!$B$2:$B$401,$A14) -> 730388355
A15: 46161 | B15: =SUMIFS(Data!$G$2:$G$401,Data!$B$2:$B$401,$A15) -> 734134419
A16: 46168 | B16: =SUMIFS(Data!$G$2:$G$401,Data!$B$2:$B$401,$A16) -> 717722128
A17: 46175 | B17: =SUMIFS(Data!$G$2:$G$401,Data!$B$2:$B$401,$A17) -> 708036364
A18: 46182 | B18: =SUMIFS(Data!$G$2:$G$401,Data!$B$2:$B$401,$A18) -> 789668399
A19: 46189 | B19: =SUMIFS(Data!$G$2:$G$401,Data!$B$2:$B$401,$A19) -> 715182613
A21: Weekly Trend — Hours Viewed by Category
A22: Week | B22: Films (English) | C22: Films (Non-English) | D22: TV (English) | E22: TV (Non-English)
A23: 46126 | B23: =SUMIFS(Data!$G$2:$G$401,Data!$B$2:$B$401,$A23,Data!$A$2:$A$401,B$22) -> 187592512 | C23: =SUMIFS(Data!$G$2:$G$401,Data!$B$2:$B$401,$A23,Data!$A$2:$A$401,C$22) -> 209498421 | D23: =SUMIFS(Data!$G$2:$G$401,Data!$B$2:$B$401,$A23,Data!$A$2:$A$401,D$22) -> 171020738 | E23: =SUMIFS(Data!$G$2:$G$401,Data!$B$2:$B$401,$A23,Data!$A$2:$A$401,E$22) -> 210730799
A24: 46133 | B24: =SUMIFS(Data!$G$2:$G$401,Data!$B$2:$B$401,$A24,Data!$A$2:$A$401,B$22) -> 172479220 | C24: =SUMIFS(Data!$G$2:$G$401,Data!$B$2:$B$401,$A24,Data!$A$2:$A$401,C$22) -> 182078870 | D24: =SUMIFS(Data!$G$2:$G$401,Data!$B$2:$B$401,$A24,Data!$A$2:$A$401,D$22) -> 190219667 | E24: =SUMIFS(Data!$G$2:$G$401,Data!$B$2:$B$401,$A24,Data!$A$2:$A$401,E$22) -> 209472600
A25: 46140 | B25: =SUMIFS(Data!$G$2:$G$401,Data!$B$2:$B$401,$A25,Data!$A$2:$A$401,B$22) -> 186573116 | C25: =SUMIFS(Data!$G$2:$G$401,Data!$B$2:$B$401,$A25,Data!$A$2:$A$401,C$22) -> 213167551 | D25: =SUMIFS(Data!$G$2:$G$401,Data!$B$2:$B$401,$A25,Data!$A$2:$A$401,D$22) -> 160379813 | E25: =SUMIFS(Data!$G$2:$G$401,Data!$B$2:$B$401,$A25,Data!$A$2:$A$401,E$22) -> 220323183
A26: 46147 | B26: =SUMIFS(Data!$G$2:$G$401,Data!$B$2:$B$401,$A26,Data!$A$2:$A$401,B$22) -> 190280546 | C26: =SUMIFS(Data!$G$2:$G$401,Data!$B$2:$B$401,$A26,Data!$A$2:$A$401,C$22) -> 189187174 | D26: =SUMIFS(Data!$G$2:$G$401,Data!$B$2:$B$401,$A26,Data!$A$2:$A$401,D$22) -> 163716807 | E26: =SUMIFS(Data!$G$2:$G$401,Data!$B$2:$B$401,$A26,Data!$A$2:$A$401,E$22) -> 197408927
A27: 46154 | B27: =SUMIFS(Data!$G$2:$G$401,Data!$B$2:$B$401,$A27,Data!$A$2:$A$401,B$22) -> 184060733 | C27: =SUMIFS(Data!$G$2:$G$401,Data!$B$2:$B$401,$A27,Data!$A$2:$A$401,C$22) -> 174758404 | D27: =SUMIFS(Data!$G$2:$G$401,Data!$B$2:$B$401,$A27,Data!$A$2:$A$401,D$22) -> 182655677 | E27: =SUMIFS(Data!$G$2:$G$401,Data!$B$2:$B$401,$A27,Data!$A$2:$A$401,E$22) -> 188913541
A28: 46161 | B28: =SUMIFS(Data!$G$2:$G$401,Data!$B$2:$B$401,$A28,Data!$A$2:$A$401,B$22) -> 185229116 | C28: =SUMIFS(Data!$G$2:$G$401,Data!$B$2:$B$401,$A28,Data!$A$2:$A$401,C$22) -> 172269834 | D28: =SUMIFS(Data!$G$2:$G$401,Data!$B$2:$B$401,$A28,Data!$A$2:$A$401,D$22) -> 183255114 | E28: =SUMIFS(Data!$G$2:$G$401,Data!$B$2:$B$401,$A28,Data!$A$2:$A$401,E$22) -> 193380355
A29: 46168 | B29: =SUMIFS(Data!$G$2:$G$401,Data!$B$2:$B$401,$A29,Data!$A$2:$A$401,B$22) -> 158204492 | C29: =SUMIFS(Data!$G$2:$G$401,Data!$B$2:$B$401,$A29,Data!$A$2:$A$401,C$22) -> 193533865 | D29: =SUMIFS(Data!$G$2:$G$401,Data!$B$2:$B$401,$A29,Data!$A$2:$A$401,D$22) -> 170592163 | E29: =SUMIFS(Data!$G$2:$G$401,Data!$B$2:$B$401,$A29,Data!$A$2:$A$401,E$22) -> 195391608
A30: 46175 | B30: =SUMIFS(Data!$G$2:$G$401,Data!$B$2:$B$401,$A30,Data!$A$2:$A$401,B$22) -> 149293285 | C30: =SUMIFS(Data!$G$2:$G$401,Data!$B$2:$B$401,$A30,Data!$A$2:$A$401,C$22) -> 198144689 | D30: =SUMIFS(Data!$G$2:$G$401,Data!$B$2:$B$401,$A30,Data!$A$2:$A$401,D$22) -> 181774691 | E30: =SUMIFS(Data!$G$2:$G$401,Data!$B$2:$B$401,$A30,Data!$A$2:$A$401,E$22) -> 178823699
A31: 46182 | B31: =SUMIFS(Data!$G$2:$G$401,Data!$B$2:$B$401,$A31,Data!$A$2:$A$401,B$22) -> 195753760 | C31: =SUMIFS(Data!$G$2:$G$401,Data!$B$2:$B$401,$A31,Data!$A$2:$A$401,C$22) -> 201365936 | D31: =SUMIFS(Data!$G$2:$G$401,Data!$B$2:$B$401,$A31,Data!$A$2:$A$401,D$22) -> 186186505 | E31: =SUMIFS(Data!$G$2:$G$401,Data!$B$2:$B$401,$A31,Data!$A$2:$A$401,E$22) -> 206362198
A32: 46189 | B32: =SUMIFS(Data!$G$2:$G$401,Data!$B$2:$B$401,$A32,Data!$A$2:$A$401,B$22) -> 179796963 | C32: =SUMIFS(Data!$G$2:$G$401,Data!$B$2:$B$401,$A32,Data!$A$2:$A$401,C$22) -> 188386440 | D32: =SUMIFS(Data!$G$2:$G$401,Data!$B$2:$B$401,$A32,Data!$A$2:$A$401,D$22) -> 147983461 | E32: =SUMIFS(Data!$G$2:$G$401,Data!$B$2:$B$401,$A32,Data!$A$2:$A$401,E$22) -> 199015749
A34: Most Recent Week — Top 10: Films (English)
A35: Rank | B35: Title | C35: Hours Viewed
A36: 1 | B36: =IFERROR(INDEX(Data!$C$2:$C$401,MATCH(1,(Data!$A$2:$A$401="Films (English)")*(Data!$B$2:$B$401=MAX(Data!$B$2:$B$401))*(Data!$F$2:$F$401=$A36),0)),"") -> Midnight Cargo | C36: =IFERROR(INDEX(Data!$G$2:$G$401,MATCH(1,(Data!$A$2:$A$401="Films (English)")*(Data!$B$2:$B$401=MAX(Data!$B$2:$B$401))*(Data!$F$2:$F$401=$A36),0)),"") -> 29774515
A37: 2 | B37: =IFERROR(INDEX(Data!$C$2:$C$401,MATCH(1,(Data!$A$2:$A$401="Films (English)")*(Data!$B$2:$B$401=MAX(Data!$B$2:$B$401))*(Data!$F$2:$F$401=$A37),0)),"") -> The Last Signal | C37: =IFERROR(INDEX(Data!$G$2:$G$401,MATCH(1,(Data!$A$2:$A$401="Films (English)")*(Data!$B$2:$B$401=MAX(Data!$B$2:$B$401))*(Data!$F$2:$F$401=$A37),0)),"") -> 26035979
A38: 3 | B38: =IFERROR(INDEX(Data!$C$2:$C$401,MATCH(1,(Data!$A$2:$A$401="Films (English)")*(Data!$B$2:$B$401=MAX(Data!$B$2:$B$401))*(Data!$F$2:$F$401=$A38),0)),"") -> Glass Harbor | C38: =IFERROR(INDEX(Data!$G$2:$G$401,MATCH(1,(Data!$A$2:$A$401="Films (English)")*(Data!$B$2:$B$401=MAX(Data!$B$2:$B$401))*(Data!$F$2:$F$401=$A38),0)),"") -> 25592326
A39: 4 | B39: =IFERROR(INDEX(Data!$C$2:$C$401,MATCH(1,(Data!$A$2:$A$401="Films (English)")*(Data!$B$2:$B$401=MAX(Data!$B$2:$B$401))*(Data!$F$2:$F$401=$A39),0)),"") -> The Forgotten Wing | C39: =IFERROR(INDEX(Data!$G$2:$G$401,MATCH(1,(Data!$A$2:$A$401="Films (English)")*(Data!$B$2:$B$401=MAX(Data!$B$2:$B$401))*(Data!$F$2:$F$401=$A39),0)),"") -> 25335934
A40: 5 | B40: =IFERROR(INDEX(Data!$C$2:$C$401,MATCH(1,(Data!$A$2:$A$401="Films (English)")*(Data!$B$2:$B$401=MAX(Data!$B$2:$B$401))*(Data!$F$2:$F$401=$A40),0)),"") -> Ridgeline | C40: =IFERROR(INDEX(Data!$G$2:$G$401,MATCH(1,(Data!$A$2:$A$401="Films (English)")*(Data!$B$2:$B$401=MAX(Data!$B$2:$B$401))*(Data!$F$2:$F$401=$A40),0)),"") -> 20476658
A41: 6 | B41: =IFERROR(INDEX(Data!$C$2:$C$401,MATCH(1,(Data!$A$2:$A$401="Films (English)")*(Data!$B$2:$B$401=MAX(Data!$B$2:$B$401))*(Data!$F$2:$F$401=$A41),0)),"") -> Quiet Storm | C41: =IFERROR(INDEX(Data!$G$2:$G$401,MATCH(1,(Data!$A$2:$A$401="Films (English)")*(Data!$B$2:$B$401=MAX(Data!$B$2:$B$401))*(Data!$F$2:$F$401=$A41),0)),"") -> 19268922
A42: 7 | B42: =IFERROR(INDEX(Data!$C$2:$C$401,MATCH(1,(Data!$A$2:$A$401="Films (English)")*(Data!$B$2:$B$401=MAX(Data!$B$2:$B$401))*(Data!$F$2:$F$401=$A42),0)),"") -> Northbound | C42: =IFERROR(INDEX(Data!$G$2:$G$401,MATCH(1,(Data!$A$2:$A$401="Films (English)")*(Data!$B$2:$B$401=MAX(Data!$B$2:$B$401))*(Data!$F$2:$F$401=$A42),0)),"") -> 11807944
A43: 8 | B43: =IFERROR(INDEX(Data!$C$2:$C$401,MATCH(1,(Data!$A$2:$A$401="Films (English)")*(Data!$B$2:$B$401=MAX(Data!$B$2:$B$401))*(Data!$F$2:$F$401=$A43),0)),"") -> Crimson Tide Rising | C43: =IFERROR(INDEX(Data!$G$2:$G$401,MATCH(1,(Data!$A$2:$A$401="Films (English)")*(Data!$B$2:$B$401=MAX(Data!$B$2:$B$401))*(Data!$F$2:$F$401=$A43),0)),"") -> 8254767
...

Sheet Data
A1: category | B1: week | C1: show_title | D1: season_title | E1: cumulative_weeks_in_top10 | F1: weekly_rank | G1: weekly_hours_viewed | H1: weekly_views | I1: runtime
A2: Films (English) | B2: 46126 | C2: Midnight Cargo | E2: 1 | F2: 1 | G2: 32290768 | H2: 17638842 | I2: 1:07
A3: Films (English) | B3: 46126 | C3: The Last Signal | E3: 1 | F3: 2 | G3: 27452835 | H3: 16037389 | I3: 1:55
A4: Films (English) | B4: 46126 | C4: Echo Park | E4: 1 | F4: 3 | G4: 23214383 | H4: 13190540 | I4: 2:08
A5: Films (English) | B5: 46126 | C5: Glass Harbor | E5: 1 | F5: 4 | G5: 22582720 | H5: 10128871 | I5: 0:42
A6: Films (English) | B6: 46126 | C6: Quiet Storm | E6: 1 | F6: 5 | G6: 21264437 | H6: 9974496 | I6: 1:32
A7: Films (English) | B7: 46126 | C7: Heist at Dawn | E7: 1 | F7: 6 | G7: 17077386 | H7: 7676667 | I7: 1:58
A8: Films (English) | B8: 46126 | C8: Ridgeline | E8: 1 | F8: 7 | G8: 14552555 | H8: 7397851 | I8: 1:36
A9: Films (English) | B9: 46126 | C9: Northbound | E9: 1 | F9: 8 | G9: 12284872 | H9: 7176423 | I9: 1:43
A10: Films (English) | B10: 46126 | C10: Saltwater | E10: 1 | F10: 9 | G10: 9938864 | H10: 5875338 | I10: 1:29
A11: Films (English) | B11: 46126 | C11: Vermillion Heights | E11: 1 | F11: 10 | G11: 6933692 | H11: 3507396 | I11: 1:54
A12: Films (Non-English) | B12: 46126 | C12: Stille Nacht | E12: 1 | F12: 1 | G12: 30564432 | H12: 18888274 | I12: 0:53
A13: Films (Non-English) | B13: 46126 | C13: Il Silenzio | E13: 1 | F13: 2 | G13: 27956015 | H13: 12836299 | I13: 0:51
... A21: Films (Non-English) | B21: 46126 | C21: Kage no Machi | E21: 1 | F21: 10 | G21: 9333693 | H21: 5508538 | I21: 0:51
A22: TV (English) | B22: 46126 | C22: Driftwood | D22: Season 2 | E22: 1 | F22: 1 | G22: 28477989 | H22: 17077686 | I22: 2:03
A23: TV (English) | B23: 46126 | C23: The Quiet Ward | D23: Season 2 | E23: 1 | F23: 2 | G23: 24594416 | H23: 15058192 | I23: 1:01
A24: TV (English) | B24: 46126 | C24: Maternal Instinct | D24: Season 1 | E24: 1 | F24: 3 | G24: 22351240 | H24: 11991722 | I24: 1:53
A25: TV (English) | B25: 46126 | C25: The Long Shift | D25: Season 2 | E25: 1 | F25: 4 | G25: 19560742 | H25: 11624461 | I25: 1:00
A26: TV (English) | B26: 46126 | C26: Backline | D26: Season 3 | E26: 1 | F26: 5 | G26: 19044768 | H26: 10967491 | I26: 1:14
A27: TV (English) | B27: 46126 | C27: Pier 9 | D27: Season 2 | E27: 1 | F27: 6 | G27: 15055818 | H27: 7291486 | I27: 1:30
A28: TV (English) | B28: 46126 | C28: Sweet Magnolias | D28: Season 1 | E28: 1 | F28: 7 | G28: 14983336 | H28: 7228784 | I28: 1:13
A29: TV (English) | B29: 46126 | C29: Lower Dispatch | D29: Season 2 | E29: 1 | F29: 8 | G29: 11498780 | H29: 4858268 | I29: 1:27
A30: TV (English) | B30: 46126 | C30: Cul-de-Sac | D30: Season 1 | E30: 1 | F30: 9 | G30: 8120558 | H30: 3647741 | I30: 0:49
A31: TV (English) | B31: 46126 | C31: Falcon's Rest | D31: Season 2 | E31: 1 | F31: 10 | G31: 7333091 | H31: 3686217 | I31: 1:54
A32: TV (Non-English) | B32: 46126 | C32: Tormenta Roja | D32: Season 1 | E32: 1 | F32: 1 | G32: 30072129 | H32: 13385610 | I32: 2:26
A33: TV (Non-English) | B33: 46126 | C33: Hora Cero | D33: Season 1 | E33: 1 | F33: 2 | G33: 27169312 | H33: 11501116 | I33: 1:50
... A41: TV (Non-English) | B41: 46126 | C41: Solntse Nochyu | D41: Season 2 | E41: 1 | F41: 10 | G41: 6501975 | H41: 3053532 | I41: 1:26
A42: Films (English) | B42: 46133 | C42: Midnight Cargo | E42: 2 | F42: 1 | G42: 31202288 | H42: 15110847 | I42: 1:27
A43: Films (English) | B43: 46133 | C43: Echo Park | E43: 2 | F43: 2 | G43: 23107562 | H43: 10300702 | I43: 1:03
A44: Films (English) | B44: 46133 | C44: The Last Signal | E44: 2 | F44: 3 | G44: 22829413 | H44: 10509203 | I44: 0:51
A45: Films (English) | B45: 46133 | C45: Glass Harbor | E45: 2 | F45: 4 | G45: 22567999 | H45: 13237557 | I45: 2:01
A46: Films (English) | B46: 46133 | C46: Quiet Storm | E46: 2 | F46: 5 | G46: 21071022 | H46: 12401991 | I46: 1:43
A47: Films (English) | B47: 46133 | C47: Ridgeline | E47: 2 | F47: 6 | G47: 16388098 | H47: 8544089 | I47: 2:22
A48: Films (English) | B48: 46133 | C48: Northbound | E48: 2 | F48: 7 | G48: 10825278 | H48: 5880877 | I48: 0:56
A49: Films (English) | B49: 46133 | C49: Saltwater | E49: 2 | F49: 8 | G49: 10352964 | H49: 4859881 | I49: 1:34
A50: Films (English) | B50: 46133 | C50: Crimson Tide Rising | E50: 1 | F50: 9 | G50: 8997233 | H50: 3805133 | I50: 1:38
A51: Films (English) | B51: 46133 | C51: Vermillion Heights | E51: 2 | F51: 10 | G51: 5137363 | H51: 2195598 | I51: 1:12
A52: Films (Non-English) | B52: 46133 | C52: La Casa Roja | E52: 2 | F52: 1 | G52: 28793123 | H52: 14667040 | I52: 1:39
A53: Films (Non-English) | B53: 46133 | C53: Khoonsard | E53: 2 | F53: 2 | G53: 23074423 | H53: 12895566 | I53: 1:08
... A61: Films (Non-English) | B61: 46133 | C61: Kage no Machi | E61: 2 | F61: 10 | G61: 7883804 | H61: 4313331 | I61: 0:59
...

Sheet ReadMe
B1: Netflix Top 10 — Dashboard Guide
B3: This workbook analyzes Netflix's official Global Top 10 (most-watched films & TV). It ships with 10 weeks of realistic SAMPLE data, structured exactly like Netflix's real export, so every chart and KPI works out of the box.
B5: What's in each tab
B6: • Dashboard — KPI cards, Top 10 bar chart, category trend lines, category share pie, total-hours trend. • Summary — the formulas (SUMIFS/COUNTIFS/AVERAGEIFS/INDEX-MATCH) that power the dashboard. Everything recalculates automatically if the Data tab changes. • Data — the raw weekly Top 10 table (Excel Table named Top10Data). • ReadMe — this page.
B8: Using real, live Netflix data instead of the sample
B9: Netflix has no public API, and its official Top 10 only updates weekly (every Tuesday). To replace the sample rows with the real feed: 1. Data tab → Data ribbon → Get Data → From Web. 2. Paste Netflix's official data file URL (grab the current link from the "Download details" button at netflix.com/tudum/top10 — as of this writing: https://www.netflix.com/tudum/top10/data/all-weeks-global.tsv). 3. Load it in, replacing the Top10Data table, keeping the same column names (category, week, show_title, season_title, cumulative_weeks_in_top10, weekly_rank, weekly_hours_viewed, weekly_views, runtime). 4. Every formula on Summary and Dashboard references the Data tab by column, so once the real columns line up, all KPIs and charts update instantly on Refresh All. (Full step-by-step Power Query setup, plus how to automate the refresh, was covered in the companion 'Power BI Guide' — the same source and M code work here too.)
B11: Changing which category the Top 10 chart shows
B12: The bar chart on Dashboard defaults to 'Films (English)'. To change it, edit the focus category text in the Summary tab's Block D formulas (Find & Replace 'Films (English)' with, e.g., 'TV (Non-English)').
B14: Keeping this current
B15: Click Data > Refresh All any time after connecting to live data, and every KPI, table, and chart updates — nothing here is hardcoded.
